Workbook

Sheet Расчёт
A1: Лабораторная работа №2. Оценка рисков и себестоимости проекта
A2: АС «База детейлинг студии». Силантьев К.Д., ЗПИуд-123. Дата: 13.10.2026.
B4: Трудозатраты, чел.-ч | C4: Стоимость, руб. | G4: Срок, мес. | H4: Специалистов
B5: =H62 -> 2943.1073 | C5: =H65 -> 1642709 | G5: =H70 -> 6.1029406 | H5: =H72 -> 4
A7: 1. Разработка и тестирование
F8: AJAX | G8: 1.5
A9: № | B9: Прецедент | C9: Сценарий и обоснование | D9: Ранг | E9: Научный 0/1 | F9: База, чел.-ч | G9: Коэф. техн. | H9: Итого, чел.-ч
A10: 1 | B10: Вход в систему | C10: Проверка учётных данных, выдача JWT и завершение сессии. | D10: 2 | E10: 0 | F10: =IF(E10=1,VLOOKUP(D10,$A$79:$C$83,3,FALSE),VLOOKUP(D10,$A$79:$C$83,2,FALSE)) -> 45 | G10: =$G$8 -> 1.5 | H10: =F10*G10 -> 67.5
A11: 2 | B11: Настройка ролей | C11: Администратор назначает роли; сервер проверяет права менеджера и мастера. | D11: 3 | E11: 0 | F11: =IF(E11=1,VLOOKUP(D11,$A$79:$C$83,3,FALSE),VLOOKUP(D11,$A$79:$C$83,2,FALSE)) -> 58 | G11: =$G$8 -> 1.5 | H11: =F11*G11 -> 87
A12: 3 | B12: Справочник услуг | C12: Изменение цены и длительности услуги с сохранением действующих заказов. | D12: 2 | E12: 0 | F12: =IF(E12=1,VLOOKUP(D12,$A$79:$C$83,3,FALSE),VLOOKUP(D12,$A$79:$C$83,2,FALSE)) -> 45 | G12: =$G$8 -> 1.5 | H12: =F12*G12 -> 67.5
A13: 4 | B13: Карточка клиента и авто | C13: Контакты клиента, несколько автомобилей, поиск и проверка полей. | D13: 3 | E13: 0 | F13: =IF(E13=1,VLOOKUP(D13,$A$79:$C$83,3,FALSE),VLOOKUP(D13,$A$79:$C$83,2,FALSE)) -> 58 | G13: =$G$8 -> 1.5 | H13: =F13*G13 -> 87
A14: 5 | B14: Календарь доступности | C14: Вывод свободных интервалов с учётом длительности услуги и мастера. | D14: 3 | E14: 0 | F14: =IF(E14=1,VLOOKUP(D14,$A$79:$C$83,3,FALSE),VLOOKUP(D14,$A$79:$C$83,2,FALSE)) -> 58 | G14: =$G$8 -> 1.5 | H14: =F14*G14 -> 87
A15: 6 | B15: Создание онлайн-записи | C15: Сохранение визита; транзакционная защита от одновременного занятия интервала. | D15: 4 | E15: 0 | F15: =IF(E15=1,VLOOKUP(D15,$A$79:$C$83,3,FALSE),VLOOKUP(D15,$A$79:$C$83,2,FALSE)) -> 71 | G15: =$G$8 -> 1.5 | H15: =F15*G15 -> 106.5
A16: 7 | B16: Перенос и отмена визита | C16: Проверка нового времени, обновление календаря и связанного задания. | D16: 3 | E16: 0 | F16: =IF(E16=1,VLOOKUP(D16,$A$79:$C$83,3,FALSE),VLOOKUP(D16,$A$79:$C$83,2,FALSE)) -> 58 | G16: =$G$8 -> 1.5 | H16: =F16*G16 -> 87
A17: 8 | B17: Распределение заданий | C17: Назначение мастера и отображение его очереди работ. | D17: 3 | E17: 0 | F17: =IF(E17=1,VLOOKUP(D17,$A$79:$C$83,3,FALSE),VLOOKUP(D17,$A$79:$C$83,2,FALSE)) -> 58 | G17: =$G$8 -> 1.5 | H17: =F17*G17 -> 87
A18: 9 | B18: Выполнение работы | C18: Начало и завершение своего задания, время и допустимые статусы. | D18: 3 | E18: 0 | F18: =IF(E18=1,VLOOKUP(D18,$A$79:$C$83,3,FALSE),VLOOKUP(D18,$A$79:$C$83,2,FALSE)) -> 58 | G18: =$G$8 -> 1.5 | H18: =F18*G18 -> 87
A19: 10 | B19: Фото до и после | C19: Загрузка фото в MinIO, привязка к визиту, права просмотра и удаление. | D19: 3 | E19: 0 | F19: =IF(E19=1,VLOOKUP(D19,$A$79:$C$83,3,FALSE),VLOOKUP(D19,$A$79:$C$83,2,FALSE)) -> 58 | G19: =$G$8 -> 1.5 | H19: =F19*G19 -> 87
A20: 11 | B20: Приёмка материалов | C20: Приход химии по номенклатуре, количеству и единице измерения. | D20: 2 | E20: 0 | F20: =IF(E20=1,VLOOKUP(D20,$A$79:$C$83,3,FALSE),VLOOKUP(D20,$A$79:$C$83,2,FALSE)) -> 45 | G20: =$G$8 -> 1.5 | H20: =F20*G20 -> 67.5
A21: 12 | B21: Списание химии | C21: Расход по заказу, атомарное изменение остатка, запрет отрицательного остатка. | D21: 4 | E21: 0 | F21: =IF(E21=1,VLOOKUP(D21,$A$79:$C$83,3,FALSE),VLOOKUP(D21,$A$79:$C$83,2,FALSE)) -> 71 | G21: =$G$8 -> 1.5 | H21: =F21*G21 -> 106.5
... A29: 20 | B29: Оффлайн и синхронизация | C29: Очередь изменений без сети, повторная передача и разрешение конфликтов. | D29: 5 | E29: 0 | F29: =IF(E29=1,VLOOKUP(D29,$A$79:$C$83,3,FALSE),VLOOKUP(D29,$A$79:$C$83,2,FALSE)) -> 94 | G29: =$G$8 -> 1.5 | H29: =F29*G29 -> 141
B30: Итого разработка и тестирование | F30: =SUM(F10:F29) -> 1196 | H30: =SUM(H10:H29) -> 1794
A32: 2. Дополнительная документация
B33: Полное руководство пользователя | G33: чел.-ч | H33: 28
B34: Полное руководство администратора | G34: чел.-ч | H34: 20
B35: Инструкция по развёртыванию и сопровождению | G35: чел.-ч | H35: 24
B36: Итого дополнительная документация | G36: чел.-ч | H36: =SUM(H33:H35) -> 72
A38: 3. Управление проектом
B39: Доля управления от разработки и тестирования | G39: доля | H39: 0.25
B40: Трудозатраты на управление | G40: чел.-ч | H40: =H30*H39 -> 448.5
A42: 4. Коэффициенты внешних рисков
B43: Неуточнённый интерфейс эквайринга | G43: коэф. | H43: 1.1
B44: Неуточнённые правила бонусов заказчика | G44: коэф. | H44: 1.05
B45: Неуточнённые правила оффлайн-синхронизации | G45: коэф. | H45: 1.08
B46: Общий коэффициент риска | G46: коэф. | H46: =PRODUCT(H43:H45) -> 1.2474
A48: 5. Дополнительные работы
B49: Первичное развёртывание приложения | G49: чел.-ч | H49: 16
B50: Перенос и проверка начальных данных | G50: чел.-ч | H50: 24
B51: Подготовка и проведение двух тренингов по 4 часа | G51: чел.-ч | H51: 16
B52: Итого дополнительные работы | G52: чел.-ч | H52: =SUM(H49:H51) -> 56
A54: 6. Дополнительные денежные расходы
...

Sheet Компромиссы
A1: Матрица компромиссов АС «БДС»
A3: Фактор | B3: Фиксируется | C3: Согласовывается | D3: Принимается | E3: Обоснование
A4: Ресурсы | C4: X | E4: Команда из 6 участников; доли занятости и расходы согласуются в пределах учебного проекта.
A5: Время | B5: X | E5: Защита и завершение проекта в декабре 2026 г.; учебный срок фиксирован.
A6: Возможности | D6: X | E6: При дефиците времени сокращается объём спринта, но обязательные требования ТЗ сохраняются.
A8: Приоритет: время → ресурсы → возможности. Изменения обязательных функций согласуются с Product Owner.
A10: В первую очередь реализуются вход, запись клиентов, задания мастеров, склад и оплата услуг.
A11: Декоративные улучшения и новые функции вне ТЗ могут быть перенесены. Оффлайн, безопасность и эквайринг из ТЗ автоматически не исключаются.
A13: Источник: методичка, матрица компромиссов; ТЗ первого семестра; состав команды из ЛР №3.

Sheet Оценка рисков
A1: Список рисков и экспертная оценка
A2: Учебная модель: оценки трёх условных экспертов — Product Owner, тимлида и QA. Опрос участников не проводился.
A3: Шкала 1–5: 1 — незначительный, 2 — низкий, 3 — средний, 4 — высокий, 5 — критический риск.
A4: Рейтинг = среднее трёх обязательных оценок. При равенстве выше стоит риск с меньшим ID.
A6: ID | B6: Риск | C6: Product Owner | D6: Тимлид | E6: QA | F6: Рейтинг | G6: Место
A7: R01 | B7: Двойная запись к одному мастеру | C7: 5 | D7: 5 | E7: 5 | F7: =IF(COUNT(C7:E7)=3,AVERAGE(C7:E7),NA()) -> 5 | G7: =RANK(F7,$F$7:$F$18,0)+COUNTIF($F$7:F7,F7)-1 -> 1
A8: R02 | B8: Неверный остаток или повторное списание химии | C8: 5 | D8: 4 | E8: 5 | F8: =IF(COUNT(C8:E8)=3,AVERAGE(C8:E8),NA()) -> 4.6666667 | G8: =RANK(F8,$F$7:$F$18,0)+COUNTIF($F$7:F8,F8)-1 -> 2
A9: R03 | B9: Повторная регистрация платежа эквайринга | C9: 4 | D9: 5 | E9: 5 | F9: =IF(COUNT(C9:E9)=3,AVERAGE(C9:E9),NA()) -> 4.6666667 | G9: =RANK(F9,$F$7:$F$18,0)+COUNTIF($F$7:F9,F9)-1 -> 3
A10: R04 | B10: Потеря изменений после работы без сети | C10: 4 | D10: 4 | E10: 5 | F10: =IF(COUNT(C10:E10)=3,AVERAGE(C10:E10),NA()) -> 4.3333333 | G10: =RANK(F10,$F$7:$F$18,0)+COUNTIF($F$7:F10,F10)-1 -> 4
A11: R05 | B11: Доступ мастера к чужим данным и заданиям | C11: 4 | D11: 4 | E11: 4 | F11: =IF(COUNT(C11:E11)=3,AVERAGE(C11:E11),NA()) -> 4 | G11: =RANK(F11,$F$7:$F$18,0)+COUNTIF($F$7:F11,F11)-1 -> 5
A12: R06 | B12: Уточнение правил бонусов и отмены после реализации | C12: 4 | D12: 3 | E12: 4 | F12: =IF(COUNT(C12:E12)=3,AVERAGE(C12:E12),NA()) -> 3.6666667 | G12: =RANK(F12,$F$7:$F$18,0)+COUNTIF($F$7:F12,F12)-1 -> 6
A13: R07 | B13: Сбой сервера и невозможность восстановления за 20 минут | C13: 3 | D13: 4 | E13: 4 | F13: =IF(COUNT(C13:E13)=3,AVERAGE(C13:E13),NA()) -> 3.6666667 | G13: =RANK(F13,$F$7:$F$18,0)+COUNTIF($F$7:F13,F13)-1 -> 7
A14: R08 | B14: Недостаточная квалификация по выбранному стеку | C14: 3 | D14: 4 | E14: 3 | F14: =IF(COUNT(C14:E14)=3,AVERAGE(C14:E14),NA()) -> 3.3333333 | G14: =RANK(F14,$F$7:$F$18,0)+COUNTIF($F$7:F14,F14)-1 -> 8
A15: R09 | B15: Отклик более 2 секунд при 15 пользователях | C15: 3 | D15: 3 | E15: 4 | F15: =IF(COUNT(C15:E15)=3,AVERAGE(C15:E15),NA()) -> 3.3333333 | G15: =RANK(F15,$F$7:$F$18,0)+COUNTIF($F$7:F15,F15)-1 -> 9
A16: R10 | B16: Ошибки переноса клиентской базы и остатков | C16: 3 | D16: 3 | E16: 3 | F16: =IF(COUNT(C16:E16)=3,AVERAGE(C16:E16),NA()) -> 3 | G16: =RANK(F16,$F$7:$F$18,0)+COUNTIF($F$7:F16,F16)-1 -> 10
A17: R11 | B17: Задержка работ к декабрьской защите | C17: 3 | D17: 3 | E17: 3 | F17: =IF(COUNT(C17:E17)=3,AVERAGE(C17:E17),NA()) -> 3 | G17: =RANK(F17,$F$7:$F$18,0)+COUNTIF($F$7:F17,F17)-1 -> 11
A18: R12 | B18: Недоступность фотографий в MinIO | C18: 2 | D18: 3 | E18: 3 | F18: =IF(COUNT(C18:E18)=3,AVERAGE(C18:E18),NA()) -> 2.6666667 | G18: =RANK(F18,$F$7:$F$18,0)+COUNTIF($F$7:F18,F18)-1 -> 12
A20: Источник списка: ТЗ АС «БДС», архитектура, команда и график из ЛР №1–4 первого семестра. Оценки — учебные предположения.
A23: Последствия и меры для всех рисков
A25: ID | B25: Последствия | C25: Предотвращение | D25: Минимизация | E25: Ответственный | F25: Примечание
A26: R01 | B26: Срыв визита и конфликт с клиентом. | C26: Проверять пересечение интервалов на сервере и тестировать конкурентные запросы. | D26: Связаться с клиентами, предложить другой интервал и исправить причину конфликта. | E26: Backend и менеджер | F26: Проектный риск
A27: R02 | B27: Нехватка материалов и искажённая себестоимость услуг. | C27: Единые единицы измерения, транзакции и уникальные номера документов. | D27: Сверить склад с документами, исправить движения и провести инвентаризацию. | E27: Backend и QA | F27: Проектный риск
A28: R03 | B28: Завышенная выручка и неверный статус оплаты визита. | C28: Проверять подпись ответа и повторяемость callback по ID платежа. | D28: Сверить операции с провайдером, убрать повторный учёт и восстановить статус. | E28: Backend и тимлид | F28: Проектный риск
A29: R04 | B29: Исчезновение записей и несогласованность заданий и склада. | C29: Очередь операций, подтверждение доставки и согласованные правила конфликтов. | D29: Остановить спорную синхронизацию, восстановить журнал и вручную сверить данные. | E29: Тимлид и QA | F29: Проектный риск
A30: R05 | B30: Раскрытие клиентской информации и изменение чужой работы. | C30: Проверять роль и владельца объекта в каждом API; проводить отрицательные тесты. | D30: Отозвать сессии, ограничить доступ, исправить проверки и изучить журнал действий. | E30: Backend | F30: Проектный риск
A31: R06 | B31: Переделка расчётов и увеличение объёма разработки. | C31: Согласовать правила и граничные примеры до начала спринта. | D31: Оценить изменение и пересобрать backlog без потери обязательных функций. | E31: Product Owner | F31: Проектный риск
A32: R07 | B32: Простой студии и потеря рабочих данных. | C32: Резервные копии БД и фото, мониторинг, тренировочное восстановление. | D32: Восстановить сервис, сверить записи и материалы, зарегистрировать потерянные операции. | E32: Тимлид | F32: Проектный риск
A33: R08 | B33: Задержка задач и ошибки в интеграциях. | C33: Обучение, ревью и парная работа над сложными функциями. | D33: Подключить тимлида и перераспределить задачи текущего спринта. | E33: Тимлид | F33: Внутренний риск; не входит в денежный коэффициент.
A34: R09 | B34: Замедление календаря и несоблюдение ТЗ. | C34: Нагрузочные прогоны, индексы и контроль времени API. | D34: Оптимизировать запросы и проверить выделенные ресурсы. | E34: Backend и QA | F34: Проектный риск
A35: R10 | B35: Дубли клиентов и неверные стартовые данные. | C35: Согласовать формат выгрузки и проверить пробный импорт. | D35: Откатить импорт, исправить соответствие полей и повторить загрузку. | E35: Backend | F35: Проектный риск
A36: R11 | B36: Не готова часть функций или отчёт. | C36: Планировать спринты по готовым результатам и оставить резерв на проверки. | D36: Перераспределить работу и отложить улучшения вне обязательного объёма. | E36: Scrum Master | F36: Внутренний риск; не входит в денежный коэффициент.
A37: R12 | B37: Нельзя подтвердить состояние автомобиля до и после услуг. | C37: Проверять права хранения и восстановление объектов из копии. | D37: Восстановить файлы и проверить ссылки на фото в карточках визитов. | E37: Backend | F37: Проектный риск

Sheet Анализ рисков
A1: Анализ пяти рисков с наибольшим рейтингом
A2: Список обновляется автоматически при изменении экспертных оценок.
A4: Место | B4: Риск | C4: Рейтинг | D4: Последствия | E4: Предотвращение | F4: Минимизация | G4: Ответственный
A5: 1 | B5: =INDEX('Оценка рисков'!$B$7:$B$18,MATCH(A5,'Оценка рисков'!$G$7:$G$18,0)) -> Двойная запись к одному мастеру | C5: =INDEX('Оценка рисков'!$F$7:$F$18,MATCH(A5,'Оценка рисков'!$G$7:$G$18,0)) -> 5 | D5: =INDEX('Оценка рисков'!$B$26:$B$37,MATCH(INDEX('Оценка рисков'!$A$7:$A$18,MATCH(A5,'Оценка рисков'!$G$7:$G$18,0)),'Оценка рисков'!$A$26:$A$37,0)) -> Срыв визита и конфликт с клиентом. | E5: =INDEX('Оценка рисков'!$C$26:$C$37,MATCH(INDEX('Оценка рисков'!$A$7:$A$18,MATCH(A5,'Оценка рисков'!$G$7:$G$18,0)),'Оценка рисков'!$A$26:$A$37,0)) -> Проверять пересечение интервалов на сервере и тестировать конкурентные запросы. | F5: =INDEX('Оценка рисков'!$D$26:$D$37,MATCH(INDEX('Оценка рисков'!$A$7:$A$18,MATCH(A5,'Оценка рисков'!$G$7:$G$18,0)),'Оценка рисков'!$A$26:$A$37,0)) -> Связаться с клиентами, предложить другой интервал и исправить причину конфликта. | G5: =INDEX('Оценка рисков'!$E$26:$E$37,MATCH(INDEX('Оценка рисков'!$A$7:$A$18,MATCH(A5,'Оценка рисков'!$G$7:$G$18,0)),'Оценка рисков'!$A$26:$A$37,0)) -> Backend и менеджер
A6: 2 | B6: =INDEX('Оценка рисков'!$B$7:$B$18,MATCH(A6,'Оценка рисков'!$G$7:$G$18,0)) -> Неверный остаток или повторное списание химии | C6: =INDEX('Оценка рисков'!$F$7:$F$18,MATCH(A6,'Оценка рисков'!$G$7:$G$18,0)) -> 4.6666667 | D6: =INDEX('Оценка рисков'!$B$26:$B$37,MATCH(INDEX('Оценка рисков'!$A$7:$A$18,MATCH(A6,'Оценка рисков'!$G$7:$G$18,0)),'Оценка рисков'!$A$26:$A$37,0)) -> Нехватка материалов и искажённая себестоимость услуг. | E6: =INDEX('Оценка рисков'!$C$26:$C$37,MATCH(INDEX('Оценка рисков'!$A$7:$A$18,MATCH(A6,'Оценка рисков'!$G$7:$G$18,0)),'Оценка рисков'!$A$26:$A$37,0)) -> Единые единицы измерения, транзакции и уникальные номера документов. | F6: =INDEX('Оценка рисков'!$D$26:$D$37,MATCH(INDEX('Оценка рисков'!$A$7:$A$18,MATCH(A6,'Оценка рисков'!$G$7:$G$18,0)),'Оценка рисков'!$A$26:$A$37,0)) -> Сверить склад с документами, исправить движения и провести инвентаризацию. | G6: =INDEX('Оценка рисков'!$E$26:$E$37,MATCH(INDEX('Оценка рисков'!$A$7:$A$18,MATCH(A6,'Оценка рисков'!$G$7:$G$18,0)),'Оценка рисков'!$A$26:$A$37,0)) -> Backend и QA
A7: 3 | B7: =INDEX('Оценка рисков'!$B$7:$B$18,MATCH(A7,'Оценка рисков'!$G$7:$G$18,0)) -> Повторная регистрация платежа эквайринга | C7: =INDEX('Оценка рисков'!$F$7:$F$18,MATCH(A7,'Оценка рисков'!$G$7:$G$18,0)) -> 4.6666667 | D7: =INDEX('Оценка рисков'!$B$26:$B$37,MATCH(INDEX('Оценка рисков'!$A$7:$A$18,MATCH(A7,'Оценка рисков'!$G$7:$G$18,0)),'Оценка рисков'!$A$26:$A$37,0)) -> Завышенная выручка и неверный статус оплаты визита. | E7: =INDEX('Оценка рисков'!$C$26:$C$37,MATCH(INDEX('Оценка рисков'!$A$7:$A$18,MATCH(A7,'Оценка рисков'!$G$7:$G$18,0)),'Оценка рисков'!$A$26:$A$37,0)) -> Проверять подпись ответа и повторяемость callback по ID платежа. | F7: =INDEX('Оценка рисков'!$D$26:$D$37,MATCH(INDEX('Оценка рисков'!$A$7:$A$18,MATCH(A7,'Оценка рисков'!$G$7:$G$18,0)),'Оценка рисков'!$A$26:$A$37,0)) -> Сверить операции с провайдером, убрать повторный учёт и восстановить статус. | G7: =INDEX('Оценка рисков'!$E$26:$E$37,MATCH(INDEX('Оценка рисков'!$A$7:$A$18,MATCH(A7,'Оценка рисков'!$G$7:$G$18,0)),'Оценка рисков'!$A$26:$A$37,0)) -> Backend и тимлид
A8: 4 | B8: =INDEX('Оценка рисков'!$B$7:$B$18,MATCH(A8,'Оценка рисков'!$G$7:$G$18,0)) -> Потеря изменений после работы без сети | C8: =INDEX('Оценка рисков'!$F$7:$F$18,MATCH(A8,'Оценка рисков'!$G$7:$G$18,0)) -> 4.3333333 | D8: =INDEX('Оценка рисков'!$B$26:$B$37,MATCH(INDEX('Оценка рисков'!$A$7:$A$18,MATCH(A8,'Оценка рисков'!$G$7:$G$18,0)),'Оценка рисков'!$A$26:$A$37,0)) -> Исчезновение записей и несогласованность заданий и склада. | E8: =INDEX('Оценка рисков'!$C$26:$C$37,MATCH(INDEX('Оценка рисков'!$A$7:$A$18,MATCH(A8,'Оценка рисков'!$G$7:$G$18,0)),'Оценка рисков'!$A$26:$A$37,0)) -> Очередь операций, подтверждение доставки и согласованные правила конфликтов. | F8: =INDEX('Оценка рисков'!$D$26:$D$37,MATCH(INDEX('Оценка рисков'!$A$7:$A$18,MATCH(A8,'Оценка рисков'!$G$7:$G$18,0)),'Оценка рисков'!$A$26:$A$37,0)) -> Остановить спорную синхронизацию, восстановить журнал и вручную сверить данные. | G8: =INDEX('Оценка рисков'!$E$26:$E$37,MATCH(INDEX('Оценка рисков'!$A$7:$A$18,MATCH(A8,'Оценка рисков'!$G$7:$G$18,0)),'Оценка рисков'!$A$26:$A$37,0)) -> Тимлид и QA
A9: 5 | B9: =INDEX('Оценка рисков'!$B$7:$B$18,MATCH(A9,'Оценка рисков'!$G$7:$G$18,0)) -> Доступ мастера к чужим данным и заданиям | C9: =INDEX('Оценка рисков'!$F$7:$F$18,MATCH(A9,'Оценка рисков'!$G$7:$G$18,0)) -> 4 | D9: =INDEX('Оценка рисков'!$B$26:$B$37,MATCH(INDEX('Оценка рисков'!$A$7:$A$18,MATCH(A9,'Оценка рисков'!$G$7:$G$18,0)),'Оценка рисков'!$A$26:$A$37,0)) -> Раскрытие клиентской информации и изменение чужой работы. | E9: =INDEX('Оценка рисков'!$C$26:$C$37,MATCH(INDEX('Оценка рисков'!$A$7:$A$18,MATCH(A9,'Оценка рисков'!$G$7:$G$18,0)),'Оценка рисков'!$A$26:$A$37,0)) -> Проверять роль и владельца объекта в каждом API; проводить отрицательные тесты. | F9: =INDEX('Оценка рисков'!$D$26:$D$37,MATCH(INDEX('Оценка рисков'!$A$7:$A$18,MATCH(A9,'Оценка рисков'!$G$7:$G$18,0)),'Оценка рисков'!$A$26:$A$37,0)) -> Отозвать сессии, ограничить доступ, исправить проверки и изучить журнал действий. | G9: =INDEX('Оценка рисков'!$E$26:$E$37,MATCH(INDEX('Оценка рисков'!$A$7:$A$18,MATCH(A9,'Оценка рисков'!$G$7:$G$18,0)),'Оценка рисков'!$A$26:$A$37,0)) -> Backend
A11: Меры предотвращения применяются до наступления события; меры минимизации — после его наступления.
